<?xml version='1.0'?>
<sdf version='1.4'>
	<model name="Rover">
		<static>0</static>
		
		<!--><link name='visual'>
			<pose>0 0 4.66 0 0 0</pose>
			<visual name='chassis_vis'>
				<geometry>
					<mesh>
						<uri>model://rover/CAD.stl</uri>
					</mesh>
				</geometry>
			</visual>
		</link><-->
		
		<!-- Chassis -->
		<link name='chassis'>
			<pose>-0.5 5.6 4.66 0 0 0</pose>
			<collision name='chassis_coll'>
				<geometry>
					<box>
						<size>5.7 9.19 1.40</size>
					</box>
				</geometry>
			</collision>
			
			<visual name='chassis_vis'>
				<geometry>
					<box>
						<size>5.7 9.19 1.40</size>
					</box>
				</geometry>
			</visual>
		</link>
		
		<!-- Left Rocker 1 -->
		<link name='left_rocker_1'>
			<pose>-4.0 3.42 4.3 0.13 0 0</pose>
			<collision name='lrock_link_1_coll'>
				<geometry>
					<box>
						<size>0.1 5.94 0.47</size>
					</box>
				</geometry>
			</collision>
			
			<visual name='lrock_link_1_vis'>
				<geometry>
					<box>
						<size>0.1 5.94 0.47</size>
					</box>
				</geometry>
			</visual>
		</link>
		
		<!-- Left Rocker 2 -->
		<link name='left_rocker_2'>
			<pose>-4.0 7.39 4.6 -0.1 0 0</pose>
			<collision name='lrock_link_2_coll'>
				<geometry>
					<box>
						<size>0.1 2.3 0.47</size>
					</box>
				</geometry>
			</collision>
			
			<visual name='lrock_link_2_vis'>
				<geometry>
					<box>
						<size>0.1 2.3 0.47</size>
					</box>
				</geometry>
			</visual>
		</link>
		
		<!-- Left Rocker Joint -->
		<joint type="revolute" name="left_rocker_hinge">
			<pose>0 -1.25 0 0 0 0</pose>
			<child>left_rocker_2</child>
			<parent>left_rocker_1</parent>
			<axis>
				<xyz>0 1 0</xyz>
				<limit>
					<upper>0</upper>
					<lower>0</lower>
				</limit>
			</axis>
		</joint>
		
		<!-- Left Rocker-Chassis Joint -->
		<joint type="revolute" name="left_rocker_chassis_joint">
			<pose>0 -1.25 0 0 0 0</pose>
			<child>left_rocker_2</child>
			<parent>chassis</parent>
			<axis>
				<xyz>1 0 0</xyz>
			</axis>
		</joint>
		
		<!-- Left Rocker-Wheel Joint -->
		<joint type="revolute" name="left_rocker_wheel_joint">
			<pose>0 -1.25 0 0 0 0</pose>
			<child>left_rocker_2</child>
			<parent>rl_link_1</parent>
			<axis>
				<xyz>0 0 1</xyz>
			</axis>
		</joint>
		
		<!-- Left Bogie 1 -->
		<link name='left_bogie_1'>
			<pose>-4.0 9.69 4.45 0 0 0</pose>
			<collision name='lbog_link_1_coll'>
				<geometry>
					<box>
						<size>0.1 2.3 0.47</size>
					</box>
				</geometry>
			</collision>
			
			<visual name='lbog_link_1_vis'>
				<geometry>
					<box>
						<size>0.1 2.3 0.47</size>
					</box>
				</geometry>
			</visual>
		</link>
		
		<!-- Left Bogie 2 -->
		<link name='left_bogie_2'>
			<pose>-4.0 7.08 2.95 0.78 0 0</pose>
			<collision name='lbog_link_2_coll'>
				<geometry>
					<box>
						<size>0.1 3.35 0.47</size>
					</box>
				</geometry>
			</collision>
			
			<visual name='lbog_link_2_vis'>
				<geometry>
					<box>
						<size>0.1 3.35 0.47</size>
					</box>
				</geometry>
			</visual>
		</link>
		
		<!-- Link Joint -->
		<joint type="revolute" name="left_bogie_hinge">
			<pose>0 0 -1.67 0 0 0</pose>
			<child>left_bogie_1</child>
			<parent>left_bogie_2</parent>
			<axis>
				<xyz>0 1 0</xyz>
				<limit>
					<upper>0</upper>
					<lower>0</lower>
				</limit>
			</axis>
		</joint>
		
		<!-- Front Left Bogie-Wheel Joint -->
		<joint type="revolute" name="fl_bogie_wheel_joint">
			<pose>0 0.5 0 0 0 0</pose>
			<child>left_bogie_1</child>
			<parent>fl_link_1</parent>
			<axis>
				<xyz>0 0 1</xyz>
				<dynamics>
					<friction>2000</friction>
				</dynamics>
			</axis>
		</joint>
		
		<!-- Left Rocker-Bogie Joint -->
		<joint type="revolute" name="left_rocker_bogie_joint">
			<pose>0 0.5 0 0 0 0</pose>
			<child>left_bogie_1</child>
			<parent>left_rocker_2</parent>
			<axis>
				<xyz>1 0 0</xyz>
			</axis>
		</joint>
		
		<!-- FL Wheel Link 1 -->
		<link name='fl_link_1'>
			<pose>-3.23 10.25 3.32 0 0 0</pose>
			<collision name='fl_link_1_coll'>
				<geometry>
					<box>
						<size>1.8 0.4 0.6</size>
					</box>
				</geometry>
			</collision>
			
			<visual name='fl_link_1_vis'>
				<geometry>
					<box>
						<size>1.8 0.4 0.6</size>
					</box>
				</geometry>
			</visual>
		</link>
		
		<!-- FL Wheel Link 2 -->
		<link name='fl_link_2'>
			<pose>-2.51 10.25 2.31 0 0 0</pose>
			<collision name='fl_link_2_coll'>
				<geometry>
					<box>
						<size>0.33 0.4 1.56</size>
					</box>
				</geometry>
			</collision>
			
			<visual name='fl_link_2_vis'>
				<geometry>
					<box>
						<size>0.33 0.4 1.56</size>
					</box>
				</geometry>
			</visual>
		</link>
		
		<!-- Link Joint -->
		<joint type="revolute" name="fl_wheel_hinge">
			<pose>0 0 0.78 0 0 0</pose>
			<child>fl_link_2</child>
			<parent>fl_link_1</parent>
			<axis>
				<xyz>0 1 0</xyz>
				<limit>
					<upper>0</upper>
					<lower>0</lower>
				</limit>
			</axis>
		</joint>
		
		<!-- FL Wheel -->
		<link name="front_left_wheel">
			<pose>-4.0 10.25 1.46 0 1.5707 0</pose>
			<collision name="fl_wheel_coll">
				<geometry>
					<cylinder>
						<radius>1.46</radius>
						<length>1.70</length>
					</cylinder>
				</geometry>
			</collision>
			<visual name="fl_wheel_vis">
				<geometry>
					<cylinder>
						<radius>1.46</radius>
						<length>1.70</length>
					</cylinder>
				</geometry>
			</visual>
		</link>
		
		<!-- ML Wheel -->
		<link name="mid_left_wheel">
			<pose>-4.87 5.63 1.46 0 1.5707 0</pose>
			<collision name="ml_wheel_coll">
				<geometry>
					<cylinder>
						<radius>1.46</radius>
						<length>1.70</length>
					</cylinder>
				</geometry>
			</collision>
			<visual name="ml_wheel_vis">
				<geometry>
					<cylinder>
						<radius>1.46</radius>
						<length>1.70</length>
					</cylinder>
				</geometry>
			</visual>
		</link>
		
		<!-- RL Wheel Link 1 -->
		<link name='rl_link_1'>
			<pose>-3.54 1.2 3.32 0 0 0</pose>
			<collision name='rl_link_1_coll'>
				<geometry>
					<box>
						<size>1.8 0.4 0.6</size>
					</box>
				</geometry>
			</collision>
			
			<visual name='rl_link_1_vis'>
				<geometry>
					<box>
						<size>1.8 0.4 0.6</size>
					</box>
				</geometry>
			</visual>
		</link>
		
		<!-- RL Wheel Link 2 -->
		<link name='rl_link_2'>
			<pose>-2.81 1.2 2.31 0 0 0</pose>
			<collision name='rl_link_2_coll'>
				<geometry>
					<box>
						<size>0.33 0.4 1.56</size>
					</box>
				</geometry>
			</collision>
			
			<visual name='rl_link_2_vis'>
				<geometry>
					<box>
						<size>0.33 0.4 1.56</size>
					</box>
				</geometry>
			</visual>
		</link>
		
		<!-- Link Joint -->
		<joint type="revolute" name="rl_wheel_hinge">
			<pose>0 0 0.78 0 0 0</pose>
			<child>rl_link_2</child>
			<parent>rl_link_1</parent>
			<axis>
				<xyz>0 1 0</xyz>
				<limit>
					<upper>0</upper>
					<lower>0</lower>
				</limit>
			</axis>
		</joint>
		
		<!-- RL Wheel -->
		<link name="rear_left_wheel">
			<pose>-4.31 1.2 1.46 0 1.5707 0</pose>
			<collision name="rl_wheel_coll">
				<geometry>
					<cylinder>
						<radius>1.46</radius>
						<length>1.70</length>
					</cylinder>
				</geometry>
			</collision>
			<visual name="rl_wheel_vis">
				<geometry>
					<cylinder>
						<radius>1.46</radius>
						<length>1.70</length>
					</cylinder>
				</geometry>
			</visual>
		</link>
		
		<!-- FR Wheel Link 1 -->
		<link name='fr_link_1'>
			<pose>2.23 10.25 3.32 0 0 0</pose>
			<collision name='fr_link_1_coll'>
				<geometry>
					<box>
						<size>1.8 0.4 0.6</size>
					</box>
					<box>
						<size>0.33 0.4 1.56</size>
					</box>
				</geometry>
			</collision>
			
			<visual name='fr_link_1_vis'>
				<geometry>
					<box>
						<size>1.8 0.4 0.6</size>
					</box>
					<box>
						<size>0.33 0.4 1.56</size>
					</box>
				</geometry>
			</visual>
		</link>
		
		<!-- FR Wheel Link 2 -->
		<link name='fr_link_2'>
			<pose>1.51 10.25 2.31 0 0 0</pose>
			<collision name='fr_link_2_coll'>
				<geometry>
					<box>
						<size>0.33 0.4 1.56</size>
					</box>
				</geometry>
			</collision>
			
			<visual name='fr_link_2_vis'>
				<geometry>
					<box>
						<size>0.33 0.4 1.56</size>
					</box>
				</geometry>
			</visual>
		</link>
		
		<!-- Link Joint -->
		<joint type="revolute" name="fr_wheel_hinge">
			<pose>0 0 0.78 0 0 0</pose>
			<child>fr_link_2</child>
			<parent>fr_link_1</parent>
			<axis>
				<xyz>0 1 0</xyz>
				<limit>
					<upper>0</upper>
					<lower>0</lower>
				</limit>
			</axis>
		</joint>
		
		<!-- FR Wheel -->
		<link name="front_right_wheel">
			<pose>3.0 10.25 1.46 0 1.5707 0</pose>
			<collision name="fr_wheel_coll">
				<geometry>
					<cylinder>
						<radius>1.46</radius>
						<length>1.70</length>
					</cylinder>
				</geometry>
			</collision>
			<visual name="fr_wheel_vis">
				<geometry>
					<cylinder>
						<radius>1.46</radius>
						<length>1.70</length>
					</cylinder>
				</geometry>
			</visual>
		</link>
		
		<!-- MR Wheel -->
		<link name="mid_right_wheel">
			<pose>3.84 5.63 1.46 0 1.5707 0</pose>
			<collision name="mr_wheel_coll">
				<geometry>
					<cylinder>
						<radius>1.46</radius>
						<length>1.70</length>
					</cylinder>
				</geometry>
			</collision>
			<visual name="mr_wheel_vis">
				<geometry>
					<cylinder>
						<radius>1.46</radius>
						<length>1.70</length>
					</cylinder>
				</geometry>
			</visual>
		</link>
		
		<!-- RR Wheel Link 1 -->
		<link name='rr_link_1'>
			<pose>2.54 1.2 3.32 0 0 0</pose>
			<collision name='rr_link_1_coll'>
				<geometry>
					<box>
						<size>1.8 0.4 0.6</size>
					</box>
					<box>
						<size>0.33 0.4 1.56</size>
					</box>
				</geometry>
			</collision>
			
			<visual name='rr_link_1_vis'>
				<geometry>
					<box>
						<size>1.8 0.4 0.6</size>
					</box>
					<box>
						<size>0.33 0.4 1.56</size>
					</box>
				</geometry>
			</visual>
		</link>
		
		<!-- RR Wheel Link 2 -->
		<link name='rr_link_2'>
			<pose>1.81 1.2 2.31 0 0 0</pose>
			<collision name='rr_link_2_coll'>
				<geometry>
					<box>
						<size>0.33 0.4 1.56</size>
					</box>
				</geometry>
			</collision>
			
			<visual name='rr_link_2_vis'>
				<geometry>
					<box>
						<size>0.33 0.4 1.56</size>
					</box>
				</geometry>
			</visual>
		</link>
		
		<!-- Link Joint -->
		<joint type="revolute" name="rr_wheel_hinge">
			<pose>0 0 0.78 0 0 0</pose>
			<child>rr_link_2</child>
			<parent>rr_link_1</parent>
			<axis>
				<xyz>0 1 0</xyz>
				<limit>
					<upper>0</upper>
					<lower>0</lower>
				</limit>
			</axis>
		</joint>
		
		<!-- RR Wheel -->
		<link name="rear_right_wheel">
			<pose>3.28 1.2 1.46 0 1.5707 0</pose>
			<collision name="rr_wheel_coll">
				<geometry>
					<cylinder>
						<radius>1.46</radius>
						<length>1.70</length>
					</cylinder>
				</geometry>
			</collision>
			<visual name="rr_wheel_vis">
				<geometry>
					<cylinder>
						<radius>1.46</radius>
						<length>1.70</length>
					</cylinder>
				</geometry>
			</visual>
		</link>
		
		<!-- Right Rocker 1 -->
		<link name='right_rocker_1'>
			<pose>3.0 3.42 4.3 0.13 0 0</pose>
			<collision name='rrock_link_1_coll'>
				<geometry>
					<box>
						<size>0.1 5.94 0.47</size>
					</box>
				</geometry>
			</collision>
			
			<visual name='rrock_link_1_vis'>
				<geometry>
					<box>
						<size>0.1 5.94 0.47</size>
					</box>
				</geometry>
			</visual>
		</link>
		
		<!-- Right Rocker 2 -->
		<link name='right_rocker_2'>
			<pose>3.0 7.39 4.6 -0.1 0 0</pose>
			<collision name='rrock_link_2_coll'>
				<geometry>
					<box>
						<size>0.1 2.3 0.47</size>
					</box>
				</geometry>
			</collision>
			
			<visual name='rrock_link_2_vis'>
				<geometry>
					<box>
						<size>0.1 2.3 0.47</size>
					</box>
				</geometry>
			</visual>
		</link>
		
		<!-- Right Rocker Joint -->
		<joint type="revolute" name="right_rocker_hinge">
			<pose>0 -1.25 0 0 0 0</pose>
			<child>right_rocker_2</child>
			<parent>right_rocker_1</parent>
			<axis>
				<xyz>0 1 0</xyz>
				<limit>
					<upper>0</upper>
					<lower>0</lower>
				</limit>
			</axis>
		</joint>
		
		<!-- Right Rocker-Chassis Joint -->
		<joint type="revolute" name="right_rocker_chassis_joint">
			<pose>0 -1.25 0 0 0 0</pose>
			<child>right_rocker_2</child>
			<parent>chassis</parent>
			<axis>
				<xyz>1 0 0</xyz>
			</axis>
		</joint>
		
		<!-- Right Rocker-Wheel Joint -->
		<joint type="revolute" name="right_rocker_wheel_joint">
			<pose>0 -1.25 0 0 0 0</pose>
			<child>right_rocker_2</child>
			<parent>rr_link_1</parent>
			<axis>
				<xyz>0 0 1</xyz>
			</axis>
		</joint>
		
		<!-- Right Bogie 1 -->
		<link name='right_bogie_1'>
			<pose>3.0 9.69 4.45 0 0 0</pose>
			<collision name='rbog_link_1_coll'>
				<geometry>
					<box>
						<size>0.1 2.3 0.47</size>
					</box>
				</geometry>
			</collision>
			
			<visual name='rbog_link_1_vis'>
				<geometry>
					<box>
						<size>0.1 2.3 0.47</size>
					</box>
				</geometry>
			</visual>
		</link>
		
		<!-- Right Bogie 2 -->
		<link name='right_bogie_2'>
			<pose>3.0 7.08 2.95 0.78 0 0</pose>
			<collision name='rbog_link_2_coll'>
				<geometry>
					<box>
						<size>0.1 3.35 0.47</size>
					</box>
				</geometry>
			</collision>
			
			<visual name='rbog_link_2_vis'>
				<geometry>
					<box>
						<size>0.1 3.35 0.47</size>
					</box>
				</geometry>
			</visual>
		</link>
		
		<!-- Link Joint -->
		<joint type="revolute" name="right_bogie_hinge">
			<pose>0 0 -1.67 0 0 0</pose>
			<child>right_bogie_1</child>
			<parent>right_bogie_2</parent>
			<axis>
				<xyz>0 1 0</xyz>
				<limit>
					<upper>0</upper>
					<lower>0</lower>
				</limit>
			</axis>
		</joint>
		
		<!-- Right Rocker-Bogie Joint -->
		<joint type="revolute" name="right_rocker_bogie_joint">
			<pose>0 0.5 0 0 0 0</pose>
			<child>right_bogie_1</child>
			<parent>right_rocker_2</parent>
			<axis>
				<xyz>1 0 0</xyz>
			</axis>
		</joint>
		
		<!-- Front Right Bogie-Wheel Joint -->
		<joint type="revolute" name="fr_bogie_wheel_joint">
			<pose>0 0.5 0 0 0 0</pose>
			<child>right_bogie_1</child>
			<parent>fr_link_1</parent>
			<axis>
				<xyz>0 0 1</xyz>
			</axis>
		</joint>
		
		<joint type="revolute" name="fl_wheel_joint">
			<pose>0 0 0 0 1.5707 0</pose>
			<child>front_left_wheel</child>
			<parent>fl_link_2</parent>
			<axis>
				<xyz>1 0 0</xyz>
			</axis>
		</joint>
		
		<joint type="revolute" name="ml_wheel_joint">
			<pose>0 0 0 0 1.5707 0</pose>
			<child>mid_left_wheel</child>
			<parent>left_bogie_2</parent>
			<axis>
				<xyz>1 0 0</xyz>
			</axis>
		</joint>
		
		<joint type="revolute" name="rl_wheel_joint">
			<pose>0 0 0 0 1.5707 0</pose>
			<child>rear_left_wheel</child>
			<parent>rl_link_2</parent>
			<axis>
				<xyz>1 0 0</xyz>
			</axis>
		</joint>
		
		<joint type="revolute" name="fr_wheel_joint">
			<pose>0 0 0 0 1.5707 0</pose>
			<child>front_right_wheel</child>
			<parent>fr_link_2</parent>
			<axis>
				<xyz>1 0 0</xyz>
			</axis>
		</joint>
		
		<joint type="revolute" name="mr_wheel_joint">
			<pose>0 0 0 0 1.5707 0</pose>
			<child>mid_right_wheel</child>
			<parent>right_bogie_2</parent>
			<axis>
				<xyz>1 0 0</xyz>
			</axis>
		</joint>
		
		<joint type="revolute" name="rr_wheel_joint">
			<pose>0 0 0 0 1.5707 0</pose>
			<child>rear_right_wheel</child>
			<parent>rr_link_2</parent>
			<axis>
				<xyz>1 0 0</xyz>
			</axis>
		</joint>
		
		<!-- Left Differential Triangle 1 -->
		<link name='left_diff_triangle_1'>
			<pose>-2.4 1.0 5.36 0 0 0</pose>
			<collision name='ldiff_link_1_coll'>
				<geometry>
					<box>
						<size>1.9 0.12 0.12</size>
					</box>
				</geometry>
			</collision>
			
			<visual name='ldiff_link_1_vis'>
				<geometry>
					<box>
						<size>1.9 0.12 0.12</size>
					</box>
				</geometry>
			</visual>
		</link>
		
		<!-- Right Differential Triangle 1 -->
		<link name='right_diff_triangle_1'>
			<pose>1.4 1.0 5.36 0 0 0</pose>
			<collision name='rdiff_link_1_coll'>
				<geometry>
					<box>
						<size>1.9 0.12 0.12</size>
					</box>
				</geometry>
			</collision>
			
			<visual name='rdiff_link_1_vis'>
				<geometry>
					<box>
						<size>1.9 0.12 0.12</size>
					</box>
				</geometry>
			</visual>
		</link>
		
		<joint type="revolute" name="right_diff_chassis_joint">
			<pose>-0.95 0 0 0 1.5707 0</pose>
			<child>right_diff_triangle_1</child>
			<parent>chassis</parent>
			<axis>
				<xyz>0 1 0</xyz>
			</axis>
		</joint>
		
		<joint type="revolute" name="left_diff_chassis_joint">
			<pose>0.95 0 0 0 1.5707 0</pose>
			<child>left_diff_triangle_1</child>
			<parent>chassis</parent>
			<axis>
				<xyz>0 1 0</xyz>
			</axis>
		</joint>
		
		<!-- Left Differential Triangle 2 -->
		<link name='left_diff_triangle_2'>
			<pose>-1.45 1.0 4.66 0 0 0</pose>
			<collision name='ldiff_link_2_coll'>
				<geometry>
					<box>
						<size>0.12 0.12 1.4</size>
					</box>
				</geometry>
			</collision>
			
			<visual name='ldiff_link_2_vis'>
				<geometry>
					<box>
						<size>0.12 0.12 1.4</size>
					</box>
				</geometry>
			</visual>
		</link>
		
		<!-- Right Differential Triangle 2 -->
		<link name='right_diff_triangle_2'>
			<pose>0.45 1.0 4.66 0 0 0</pose>
			<collision name='rdiff_link_2_coll'>
				<geometry>
					<box>
						<size>0.12 0.12 1.4</size>
					</box>
				</geometry>
			</collision>
			
			<visual name='rdiff_link_2_vis'>
				<geometry>
					<box>
						<size>0.12 0.12 1.4</size>
					</box>
				</geometry>
			</visual>
		</link>
		
		<joint type="revolute" name="right_diff_right_joint">
			<pose>0 0 0.7 0 1.5707 0</pose>
			<child>right_diff_triangle_2</child>
			<parent>right_diff_triangle_1</parent>
			<axis>
				<xyz>0 1 0</xyz>
				<limit>
					<upper>0</upper>
					<lower>0</lower>
				</limit>
			</axis>
		</joint>
		
		<joint type="revolute" name="left_diff_right_joint">
			<pose>0 0 0.7 0 1.5707 0</pose>
			<child>left_diff_triangle_2</child>
			<parent>left_diff_triangle_1</parent>
			<axis>
				<xyz>0 1 0</xyz>
				<limit>
					<upper>0</upper>
					<lower>0</lower>
				</limit>
			</axis>
		</joint>
		
		<!-- Left Differential Triangle 3 -->
		<link name='left_diff_triangle_3'>
			<pose>-2.42 1.0 4.66 0 0.63 0</pose>
			<collision name='ldiff_link_3_coll'>
				<geometry>
					<box>
						<size>2.36 0.12 0.12</size>
					</box>
				</geometry>
			</collision>
			
			<visual name='ldiff_link_3_vis'>
				<geometry>
					<box>
						<size>2.36 0.12 0.12</size>
					</box>
				</geometry>
			</visual>
		</link>
		
		<!-- Right Differential Triangle 3 -->
		<link name='right_diff_triangle_3'>
			<pose>1.42 1.0 4.66 0 -0.63 0</pose>
			<collision name='rdiff_link_3_coll'>
				<geometry>
					<box>
						<size>2.36 0.12 0.12</size>
					</box>
				</geometry>
			</collision>
			
			<visual name='rdiff_link_3_vis'>
				<geometry>
					<box>
						<size>2.36 0.12 0.12</size>
					</box>
				</geometry>
			</visual>
		</link>
		
		<joint type="revolute" name="right_diff_hor_joint">
			<pose>0.95 0 0 0 1.5707 0</pose>
			<child>right_diff_triangle_1</child>
			<parent>right_diff_triangle_3</parent>
			<axis>
				<xyz>0 1 0</xyz>
				<limit>
					<upper>0</upper>
					<lower>0</lower>
				</limit>
			</axis>
		</joint>
		
		<joint type="revolute" name="left_diff_hor_joint">
			<pose>-0.95 0 0 0 1.5707 0</pose>
			<child>left_diff_triangle_1</child>
			<parent>left_diff_triangle_3</parent>
			<axis>
				<xyz>0 1 0</xyz>
				<limit>
					<upper>0</upper>
					<lower>0</lower>
				</limit>
			</axis>
		</joint>
		
		<joint type="revolute" name="right_diff_vert_joint">
			<pose>0 0 -0.7 0 1.5707 0</pose>
			<child>right_diff_triangle_2</child>
			<parent>right_diff_triangle_3</parent>
			<axis>
				<xyz>0 1 0</xyz>
				<limit>
					<upper>0</upper>
					<lower>0</lower>
				</limit>
			</axis>
		</joint>
		
		<joint type="revolute" name="left_diff_vert_joint">
			<pose>0 0 -0.7 0 1.5707 0</pose>
			<child>left_diff_triangle_2</child>
			<parent>left_diff_triangle_3</parent>
			<axis>
				<xyz>0 1 0</xyz>
				<limit>
					<upper>0</upper>
					<lower>0</lower>
				</limit>
			</axis>
		</joint>
		
		<!-- Differential Center -->
		<link name='diff_center'>
			<pose>-0.5 1.0 3.96 0 0 0</pose>
			<collision name='diff_center_coll'>
				<geometry>
					<box>
						<size>1.9 0.12 0.12</size>
					</box>
				</geometry>
			</collision>
			
			<visual name='diff_center_vis'>
				<geometry>
					<box>
						<size>1.9 0.12 0.12</size>
					</box>
				</geometry>
			</visual>
		</link>
		
		<joint type="revolute" name="right_diff_cent_joint">
			<pose>0.95 0 0 0 0 0</pose>
			<child>diff_center</child>
			<parent>right_diff_triangle_2</parent>
			<axis>
				<xyz>0 1 0</xyz>
				<limit>
					<upper>0</upper>
					<lower>0</lower>
				</limit>
			</axis>
		</joint>
		
		<joint type="revolute" name="left_diff_cent_joint">
			<pose>0.95 0 0 0 0 0</pose>
			<child>diff_center</child>
			<parent>left_diff_triangle_2</parent>
			<axis>
				<xyz>0 1 0</xyz>
				<limit>
					<upper>0</upper>
					<lower>0</lower>
				</limit>
			</axis>
		</joint>
		
		<!-- Left Differential Joint Link -->
		<link name='left_diff_joint_link'>
			<pose>-3.67 1.0 4.66 0 0.15 0</pose>
			<collision name='ldiff_link_coll'>
				<geometry>
					<box>
						<size>0.12 0.12 1.4</size>
					</box>
				</geometry>
			</collision>
			
			<visual name='ldiff_link_vis'>
				<geometry>
					<box>
						<size>0.12 0.12 1.4</size>
					</box>
				</geometry>
			</visual>
		</link>
		
		<!-- Right Differential Joint Link -->
		<link name='right_diff_joint_link'>
			<pose>2.67 1.0 4.66 0 -0.15 0</pose>
			<collision name='rdiff_link_coll'>
				<geometry>
					<box>
						<size>0.12 0.12 1.4</size>
					</box>
				</geometry>
			</collision>
			
			<visual name='rdiff_link_vis'>
				<geometry>
					<box>
						<size>0.12 0.12 1.4</size>
					</box>
				</geometry>
			</visual>
		</link>
		
		
		<!-- Ball Joints -->
		<joint type="revolute2" name="right_diff_link_rocker_joint">
			<pose>0.12 0 -0.69 0 0 0</pose>
			<child>right_diff_joint_link</child>
			<parent>right_rocker_1</parent>
			<axis>
				<xyz>1 0 0</xyz>
			</axis>
			<axis>
				<xyz>0 1 0</xyz>
			</axis>
		</joint>
		
		<joint type="revolute2" name="right_diff_link_diff_joint">
			<pose>-0.12 0 0.69 0 0 0</pose>
			<child>right_diff_joint_link</child>
			<parent>right_diff_triangle_1</parent>
			<axis>
				<xyz>1 0 0</xyz>
			</axis>
			<axis>
				<xyz>0 1 0</xyz>
			</axis>
		</joint>
		
		<joint type="revolute2" name="left_diff_link_rocker_joint">
			<pose>-0.12 20 -0.69 0 0 0</pose>
			<child>left_diff_joint_link</child>
			<parent>left_rocker_1</parent>
			<axis>
				<xyz>1 0 0</xyz>
			</axis>
			<axis>
				<xyz>0 1 0</xyz>
			</axis>
		</joint>
		
		<joint type="revolute2" name="left_diff_link_diff_joint">
			<pose>0.12 0 0.69 0 0 0</pose>
			<child>left_diff_joint_link</child>
			<parent>left_diff_triangle_1</parent>
			<axis>
				<xyz>1 0 0</xyz>
			</axis>
			<axis>
				<xyz>0 1 0</xyz>
			</axis>
		</joint>
	</model>
</sdf>
