<sdf version='1.5'>
  <world name='default'>
    <light name='sun' type='directional'>
      <cast_shadows>1</cast_shadows>
      <pose>0 0 10 0 -0 0</pose>
      <diffuse>0.8 0.8 0.8 1</diffuse>
      <specular>0.2 0.2 0.2 1</specular>
      <attenuation>
        <range>1000</range>
        <constant>0.9</constant>
        <linear>0.01</linear>
        <quadratic>0.001</quadratic>
      </attenuation>
      <direction>-0.5 0.1 -0.9</direction>
    </light>
    <model name='heightmap'>
      <static>1</static>
      <link name='link'>
        <collision name='collision'>
          <geometry>
            <heightmap>
              <uri>file://heightmaps/mtsthelens_before.dem</uri>
              <size>150 150 50</size>
              <pos>0 0 0</pos>
              <texture>
                <size>10</size>
                <diffuse>__default__</diffuse>
                <normal>__default__</normal>
              </texture>
              <blend>
                <min_height>0</min_height>
                <fade_dist>0</fade_dist>
              </blend>
            </heightmap>
          </geometry>
          <max_contacts>10</max_contacts>
          <surface>
            <contact>
              <ode/>
            </contact>
            <bounce/>
            <friction>
              <ode/>
            </friction>
          </surface>
        </collision>
        <visual name='visual_abcedf'>
          <geometry>
            <heightmap>
              <texture>
                <diffuse>file://media/materials/textures/dirt_diffusespecular.png</diffuse>
                <normal>file://media/materials/textures/flat_normal.png</normal>
                <size>1</size>
              </texture>
              <texture>
                <diffuse>file://media/materials/textures/grass_diffusespecular.png</diffuse>
                <normal>file://media/materials/textures/flat_normal.png</normal>
                <size>1</size>
              </texture>
              <texture>
                <diffuse>file://media/materials/textures/fungus_diffusespecular.png</diffuse>
                <normal>file://media/materials/textures/flat_normal.png</normal>
                <size>1</size>
              </texture>
              <blend>
                <min_height>2</min_height>
                <fade_dist>5</fade_dist>
              </blend>
              <blend>
                <min_height>4</min_height>
                <fade_dist>5</fade_dist>
              </blend>
              <uri>file://heightmaps/mtsthelens_before.dem</uri>
              <size>150 150 50</size>
              <pos>0 0 0</pos>
            </heightmap>
          </geometry>
        </visual>
        <velocity_decay>
          <linear>0</linear>
          <angular>0</angular>
        </velocity_decay>
        <self_collide>0</self_collide>
        <kinematic>0</kinematic>
        <gravity>1</gravity>
      </link>
    </model>
    <physics type='ode'>
      <max_step_size>0.001</max_step_size>
      <real_time_factor>1</real_time_factor>
      <real_time_update_rate>1000</real_time_update_rate>
      <gravity>0 0 -9.8</gravity>
    </physics>
    <scene>
      <ambient>0.4 0.4 0.4 1</ambient>
      <background>0.7 0.7 0.7 1</background>
      <shadows>1</shadows>
    </scene>
    <audio>
      <device>default</device>
    </audio>
    <spherical_coordinates>
      <surface_model>EARTH_WGS84</surface_model>
      <latitude_deg>0</latitude_deg>
      <longitude_deg>0</longitude_deg>
      <elevation>0</elevation>
      <heading_deg>0</heading_deg>
    </spherical_coordinates>
    <state world_name='default'>
      <sim_time>267 353000000</sim_time>
      <real_time>0 0</real_time>
      <wall_time>1409188493 733795907</wall_time>
      <model name='heightmap'>
        <pose>0 0 0 0 -0 0</pose>
        <link name='link'>
          <pose>0 0 0 0 -0 0</pose>
          <velocity>0 0 0 0 -0 0</velocity>
          <acceleration>0 0 0 0 -0 0</acceleration>
          <wrench>0 0 0 0 -0 0</wrench>
        </link>
      </model>
      <model name='polaris_ranger_xp900_0'>
        <pose>41.92 -64.3715 13.65 0 -0.04 1.57</pose>
        <link name='FNR_switch'>
          <pose>41.8204 -63.8779 14.8207 0 0.21 1.57</pose>
          <velocity>0 0 0 0 -0 0</velocity>
          <acceleration>0 0 0 0 -0 0</acceleration>
          <wrench>0 0 0 0 -0 0</wrench>
        </link>
        <link name='brake_pedal'>
          <pose>41.6505 -63.755 14.2551 0 -0.04 1.57</pose>
          <velocity>0 0 0 0 -0 0</velocity>
          <acceleration>0 0 0 0 -0 0</acceleration>
          <wrench>0 0 0 0 -0 0</wrench>
        </link>
        <link name='chassis'>
          <pose>41.92 -64.3715 13.65 0 -0.04 1.57</pose>
          <velocity>0 0 0 0 -0 0</velocity>
          <acceleration>0 0 0 0 -0 0</acceleration>
          <wrench>0 0 0 0 -0 0</wrench>
        </link>
        <link name='front_left_wheel'>
          <pose>41.2053 -63.1835 14.0448 -1.52 -0.04 1.57</pose>
          <velocity>0 0 0 0 -0 0</velocity>
          <acceleration>0 0 0 0 -0 0</acceleration>
          <wrench>0 0 0 0 -0 0</wrench>
        </link>
        <link name='front_left_wheel_steering_block'>
          <pose>41.4209 -63.184 14.0529 1.5708 -0.04 1.57</pose>
          <velocity>0 0 0 0 -0 0</velocity>
          <acceleration>0 0 0 0 -0 0</acceleration>
          <wrench>0 0 0 0 -0 0</wrench>
        </link>
        <link name='front_right_wheel'>
          <pose>42.6365 -63.1847 14.0448 1.52 -0.04 1.57</pose>
          <velocity>0 0 0 0 -0 0</velocity>
          <acceleration>0 0 0 0 -0 0</acceleration>
          <wrench>0 0 0 0 -0 0</wrench>
        </link>
        <link name='front_right_wheel_steering_block'>
          <pose>42.4209 -63.1848 14.0529 1.5708 -0.04 1.57</pose>
          <velocity>0 0 0 0 -0 0</velocity>
          <acceleration>0 0 0 0 -0 0</acceleration>
          <wrench>0 0 0 0 -0 0</wrench>
        </link>
        <link name='gas_pedal'>
          <pose>41.8205 -63.7651 14.2547 0 -0.04 1.57</pose>
          <velocity>0 0 0 0 -0 0</velocity>
          <acceleration>0 0 0 0 -0 0</acceleration>
          <wrench>0 0 0 0 -0 0</wrench>
        </link>
        <link name='hand_brake'>
          <pose>41.7154 -63.8838 14.7204 0 -0.04 1.57</pose>
          <velocity>0 0 0 0 -0 0</velocity>
          <acceleration>0 0 0 0 -0 0</acceleration>
          <wrench>0 0 0 0 -0 0</wrench>
        </link>
        <link name='rear_left_wheel'>
          <pose>41.2035 -65.3778 13.957 -1.52 -0.04 1.57</pose>
          <velocity>0 0 0 0 -0 0</velocity>
          <acceleration>0 0 0 0 -0 0</acceleration>
          <wrench>0 0 0 0 -0 0</wrench>
        </link>
        <link name='rear_right_wheel'>
          <pose>42.6348 -65.3789 13.957 1.52 -0.04 1.57</pose>
          <velocity>0 0 0 0 -0 0</velocity>
          <acceleration>0 0 0 0 -0 0</acceleration>
          <wrench>0 0 0 0 -0 0</wrench>
        </link>
        <link name='steering_wheel'>
          <pose>41.4603 -63.9995 14.8658 2.71339e-16 -0.91 1.57</pose>
          <velocity>0 0 0 0 -0 0</velocity>
          <acceleration>0 0 0 0 -0 0</acceleration>
          <wrench>0 0 0 0 -0 0</wrench>
        </link>
      </model>
    </state>
    <gui fullscreen='0'>
      <camera name='user_camera'>
        <pose>84.8934 -85.7628 35.1674 0 0.275643 2.35619</pose>
        <view_controller>orbit</view_controller>
      </camera>
    </gui>
    <model name='polaris_ranger_xp900_0'>
      <static>0</static>
      <link name='chassis'>
        <inertial>
          <mass>720</mass>
          <inertia>
            <ixx>140</ixx>
            <ixy>0</ixy>
            <iyy>550</iyy>
            <ixz>0</ixz>
            <iyz>0</iyz>
            <izz>550</izz>
          </inertia>
          <pose>0.1 0 0.4 0 -0 0</pose>
        </inertial>
        <visual name='visual'>
          <pose>0 0 0 0 0 -1.5708</pose>
          <geometry>
            <mesh>
              <uri>model://polaris_ranger_xp900_no_roll_cage/meshes/chasis.dae</uri>
            </mesh>
          </geometry>
          <material>
            <script>
              <uri>model://polaris_ranger_xp900/materials/scripts</uri>
              <uri>model://polaris_ranger_xp900/materials/textures</uri>
              <name>PolarisXP900/Diffuse</name>
            </script>
          </material>
        </visual>
        <collision name='chassis_bottom'>
          <pose>0.2 0 0.335 0 -0 0</pose>
          <geometry>
            <box>
              <size>1.34 1.65746 0.06</size>
            </box>
          </geometry>
          <max_contacts>10</max_contacts>
          <surface>
            <contact>
              <ode/>
            </contact>
            <bounce/>
            <friction>
              <ode/>
            </friction>
          </surface>
        </collision>
        <collision name='cargo_bottom'>
          <pose>-1 0 0.921 0 -0 0</pose>
          <geometry>
            <box>
              <size>1.04609 1.6998 0.01</size>
            </box>
          </geometry>
          <max_contacts>10</max_contacts>
          <surface>
            <contact>
              <ode/>
            </contact>
            <bounce/>
            <friction>
              <ode/>
            </friction>
          </surface>
        </collision>
        <collision name='cargo_front'>
          <pose>-0.495 0 1.06 0 -0 0</pose>
          <geometry>
            <box>
              <size>0.05 1.69982 0.27</size>
            </box>
          </geometry>
          <max_contacts>10</max_contacts>
          <surface>
            <contact>
              <ode/>
            </contact>
            <bounce/>
            <friction>
              <ode/>
            </friction>
          </surface>
        </collision>
        <collision name='cargo_back'>
          <pose>-1.465 0 1.06 0 -0 0</pose>
          <geometry>
            <box>
              <size>0.05 1.69982 0.27</size>
            </box>
          </geometry>
          <max_contacts>10</max_contacts>
          <surface>
            <contact>
              <ode/>
            </contact>
            <bounce/>
            <friction>
              <ode/>
            </friction>
          </surface>
        </collision>
        <collision name='cargo_left'>
          <pose>-0.97 0.82491 1.06 0 -0 0</pose>
          <geometry>
            <box>
              <size>1.04609 0.05 0.27</size>
            </box>
          </geometry>
          <max_contacts>10</max_contacts>
          <surface>
            <contact>
              <ode/>
            </contact>
            <bounce/>
            <friction>
              <ode/>
            </friction>
          </surface>
        </collision>
        <collision name='cargo_right'>
          <pose>-0.97 -0.82491 1.06 0 -0 0</pose>
          <geometry>
            <box>
              <size>1.04609 0.05 0.27</size>
            </box>
          </geometry>
          <max_contacts>10</max_contacts>
          <surface>
            <contact>
              <ode/>
            </contact>
            <bounce/>
            <friction>
              <ode/>
            </friction>
          </surface>
        </collision>
        <collision name='seat'>
          <pose>0 0 0.62 0 -0 0</pose>
          <geometry>
            <box>
              <size>0.52167 1.37206 0.53369</size>
            </box>
          </geometry>
          <surface>
            <contact>
              <ode>
                <min_depth>0.01</min_depth>
              </ode>
            </contact>
            <bounce/>
            <friction>
              <ode/>
            </friction>
          </surface>
          <max_contacts>10</max_contacts>
        </collision>
        <collision name='mud_seat'>
          <pose>0 0 0.86 0 -0 0</pose>
          <geometry>
            <box>
              <size>0.52167 1.3 0.1</size>
            </box>
          </geometry>
          <surface>
            <contact>
              <collide_without_contact>1</collide_without_contact>
              <ode/>
            </contact>
            <bounce/>
            <friction>
              <ode/>
            </friction>
          </surface>
          <max_contacts>10</max_contacts>
        </collision>
        <sensor name='seat_contact' type='contact'>
          <always_on>1</always_on>
          <update_rate>1000</update_rate>
          <contact>
            <collision>mud_seat</collision>
            <topic>__default_topic__</topic>
          </contact>
        </sensor>
        <collision name='seat_back'>
          <pose>-0.26 0 1.125 0 -0.2 0</pose>
          <geometry>
            <box>
              <size>0.06 1.37206 0.6</size>
            </box>
          </geometry>
          <max_contacts>10</max_contacts>
          <surface>
            <contact>
              <ode/>
            </contact>
            <bounce/>
            <friction>
              <ode/>
            </friction>
          </surface>
        </collision>
        <collision name='engine'>
          <pose>1.12 0 0.7 0 -0 0</pose>
          <geometry>
            <box>
              <size>0.58 1.3 0.8</size>
            </box>
          </geometry>
          <max_contacts>10</max_contacts>
          <surface>
            <contact>
              <ode/>
            </contact>
            <bounce/>
            <friction>
              <ode/>
            </friction>
          </surface>
        </collision>
        <collision name='central_hump1_collision'>
          <pose>0.55 -0.1 0.4 0 -0 0</pose>
          <geometry>
            <box>
              <size>0.6 0.15 0.1</size>
            </box>
          </geometry>
          <max_contacts>10</max_contacts>
          <surface>
            <contact>
              <ode/>
            </contact>
            <bounce/>
            <friction>
              <ode/>
            </friction>
          </surface>
        </collision>
        <collision name='central_hump2_collision'>
          <pose>0.7 -0.05 0.45 0 -0.5 0</pose>
          <geometry>
            <box>
              <size>0.2 0.05 0.1</size>
            </box>
          </geometry>
          <max_contacts>10</max_contacts>
          <surface>
            <contact>
              <ode/>
            </contact>
            <bounce/>
            <friction>
              <ode/>
            </friction>
          </surface>
        </collision>
        <collision name='central_hump3_collision'>
          <pose>0.798 -0.125 0.478 0 -0.8 0</pose>
          <geometry>
            <box>
              <size>0.129 0.1 0.05</size>
            </box>
          </geometry>
          <max_contacts>10</max_contacts>
          <surface>
            <contact>
              <ode/>
            </contact>
            <bounce/>
            <friction>
              <ode/>
            </friction>
          </surface>
        </collision>
        <collision name='central_hump4_collision'>
          <pose>0.8135 -0.05 0.45 0 -0 0</pose>
          <geometry>
            <box>
              <size>0.1 0.05 0.1835</size>
            </box>
          </geometry>
          <max_contacts>10</max_contacts>
          <surface>
            <contact>
              <ode/>
            </contact>
            <bounce/>
            <friction>
              <ode/>
            </friction>
          </surface>
        </collision>
        <collision name='central_hump5_collision'>
          <pose>0.84 -0.125 0.45 0 -0 0</pose>
          <geometry>
            <box>
              <size>0.03 0.1 0.1835</size>
            </box>
          </geometry>
          <max_contacts>10</max_contacts>
          <surface>
            <contact>
              <ode/>
            </contact>
            <bounce/>
            <friction>
              <ode/>
            </friction>
          </surface>
        </collision>
        <collision name='central_hump6_collision'>
          <pose>0.82 -0.125 0.475 0 -0 0</pose>
          <geometry>
            <box>
              <size>0.03 0.1 0.05</size>
            </box>
          </geometry>
          <max_contacts>10</max_contacts>
          <surface>
            <contact>
              <ode/>
            </contact>
            <bounce/>
            <friction>
              <ode/>
            </friction>
          </surface>
        </collision>
        <visual name='cargo_visual'>
          <pose>-1 0 1.0323 0 0 -1.5707</pose>
          <geometry>
            <mesh>
              <uri>model://polaris_ranger_xp900/meshes/polaris.dae</uri>
              <submesh>
                <name>Bed</name>
                <center>1</center>
              </submesh>
            </mesh>
          </geometry>
          <material>
            <script>
              <uri>model://polaris_ranger_xp900/materials/scripts</uri>
              <uri>model://polaris_ranger_xp900/materials/textures</uri>
              <name>PolarisXP900/Diffuse</name>
            </script>
          </material>
        </visual>
        <visual name='tailgate_visual'>
          <pose>-1.492 0 1.03 0 0 -1.5707</pose>
          <geometry>
            <mesh>
              <uri>model://polaris_ranger_xp900/meshes/polaris.dae</uri>
              <submesh>
                <name>Tail_Gate</name>
                <center>1</center>
              </submesh>
            </mesh>
          </geometry>
          <material>
            <script>
              <uri>model://polaris_ranger_xp900/materials/scripts</uri>
              <uri>model://polaris_ranger_xp900/materials/textures</uri>
              <name>PolarisXP900/Diffuse</name>
            </script>
          </material>
        </visual>
        <visual name='front_left_brake_visual'>
          <pose>1.12 -0.57488 0.35516 3.1415 -6.77626e-21 1.5707</pose>
          <geometry>
            <mesh>
              <uri>model://polaris_ranger_xp900/meshes/polaris.dae</uri>
              <submesh>
                <name>Brake_Front_Left</name>
                <center>1</center>
              </submesh>
            </mesh>
          </geometry>
          <material>
            <script>
              <uri>model://polaris_ranger_xp900/materials/scripts</uri>
              <uri>model://polaris_ranger_xp900/materials/textures</uri>
              <name>PolarisXP900/Diffuse</name>
            </script>
          </material>
        </visual>
        <visual name='front_right_brake_visual'>
          <pose>1.12 0.57488 0.35516 3.1415 -6.77626e-21 1.5707</pose>
          <geometry>
            <mesh>
              <uri>model://polaris_ranger_xp900/meshes/polaris.dae</uri>
              <submesh>
                <name>Brake_Front_Right</name>
                <center>1</center>
              </submesh>
            </mesh>
          </geometry>
          <material>
            <script>
              <uri>model://polaris_ranger_xp900/materials/scripts</uri>
              <uri>model://polaris_ranger_xp900/materials/textures</uri>
              <name>PolarisXP900/Diffuse</name>
            </script>
          </material>
        </visual>
        <visual name='central_hump1'>
          <pose>0.55 -0.1 0.4 0 -0 0</pose>
          <geometry>
            <box>
              <size>0.6 0.15 0.1</size>
            </box>
          </geometry>
          <material>
            <script>
              <uri>file://media/materials/scripts/gazebo.material</uri>
              <name>Gazebo/DarkGrey</name>
            </script>
          </material>
        </visual>
        <visual name='central_hump2'>
          <pose>0.7 -0.05 0.45 0 -0.5 0</pose>
          <geometry>
            <box>
              <size>0.2 0.05 0.1</size>
            </box>
          </geometry>
          <material>
            <script>
              <uri>file://media/materials/scripts/gazebo.material</uri>
              <name>Gazebo/DarkGrey</name>
            </script>
          </material>
        </visual>
        <visual name='central_hump3'>
          <pose>0.798 -0.125 0.478 0 -0.8 0</pose>
          <geometry>
            <box>
              <size>0.129 0.1 0.05</size>
            </box>
          </geometry>
          <material>
            <script>
              <uri>file://media/materials/scripts/gazebo.material</uri>
              <name>Gazebo/DarkGrey</name>
            </script>
          </material>
        </visual>
        <visual name='central_hump4'>
          <pose>0.8135 -0.05 0.45 0 -0 0</pose>
          <geometry>
            <box>
              <size>0.1 0.05 0.1835</size>
            </box>
          </geometry>
          <material>
            <script>
              <uri>file://media/materials/scripts/gazebo.material</uri>
              <name>Gazebo/DarkGrey</name>
            </script>
          </material>
        </visual>
        <visual name='central_hump5'>
          <pose>0.84 -0.125 0.45 0 -0 0</pose>
          <geometry>
            <box>
              <size>0.03 0.1 0.1835</size>
            </box>
          </geometry>
          <material>
            <script>
              <uri>file://media/materials/scripts/gazebo.material</uri>
              <name>Gazebo/DarkGrey</name>
            </script>
          </material>
        </visual>
        <visual name='central_hump6'>
          <pose>0.82 -0.125 0.475 0 -0 0</pose>
          <geometry>
            <box>
              <size>0.03 0.1 0.05</size>
            </box>
          </geometry>
          <material>
            <script>
              <uri>file://media/materials/scripts/gazebo.material</uri>
              <name>Gazebo/DarkGrey</name>
            </script>
          </material>
        </visual>
        <velocity_decay>
          <linear>0</linear>
          <angular>0</angular>
        </velocity_decay>
        <self_collide>0</self_collide>
        <kinematic>0</kinematic>
        <gravity>1</gravity>
      </link>
      <link name='front_left_wheel'>
        <pose>1.20223 0.71562 0.34697 -1.52 0 0</pose>
        <inertial>
          <mass>12</mass>
          <inertia>
            <ixx>0.5</ixx>
            <ixy>0</ixy>
            <iyy>0.5</iyy>
            <ixz>0</ixz>
            <iyz>0</iyz>
            <izz>1</izz>
          </inertia>
        </inertial>
        <collision name='collision'>
          <geometry>
            <cylinder>
              <radius>0.3175</radius>
              <length>0.2794</length>
            </cylinder>
          </geometry>
          <max_contacts>1</max_contacts>
          <surface>
            <friction>
              <ode>
                <mu>1</mu>
                <mu2>1</mu2>
                <fdir1>0 0 1</fdir1>
                <slip1>0</slip1>
                <slip2>0</slip2>
              </ode>
            </friction>
            <contact>
              <ode>
                <min_depth>0.005</min_depth>
                <kp>1e+08</kp>
              </ode>
            </contact>
            <bounce/>
          </surface>
        </collision>
        <visual name='tire_visual'>
          <pose>0 0 0 -2.65359e-06 1.57079 3.14159</pose>
          <geometry>
            <mesh>
              <uri>model://polaris_ranger_xp900/meshes/polaris.dae</uri>
              <scale>1.0037 0.8862 0.8862</scale>
              <submesh>
                <name>Wheel_Front_Left</name>
                <center>1</center>
              </submesh>
            </mesh>
          </geometry>
          <material>
            <script>
              <uri>model://polaris_ranger_xp900/materials/scripts</uri>
              <uri>model://polaris_ranger_xp900/materials/textures</uri>
              <name>PolarisXP900/Diffuse</name>
            </script>
          </material>
        </visual>
        <velocity_decay>
          <linear>0</linear>
          <angular>0</angular>
        </velocity_decay>
        <self_collide>0</self_collide>
        <kinematic>0</kinematic>
        <gravity>1</gravity>
      </link>
      <link name='front_right_wheel'>
        <pose>1.20223 -0.71562 0.34697 1.52 -0 0</pose>
        <inertial>
          <mass>12</mass>
          <inertia>
            <ixx>0.5</ixx>
            <ixy>0</ixy>
            <iyy>0.5</iyy>
            <ixz>0</ixz>
            <iyz>0</iyz>
            <izz>1</izz>
          </inertia>
        </inertial>
        <collision name='collision'>
          <geometry>
            <cylinder>
              <radius>0.3175</radius>
              <length>0.2794</length>
            </cylinder>
          </geometry>
          <max_contacts>1</max_contacts>
          <surface>
            <friction>
              <ode>
                <mu>1</mu>
                <mu2>1</mu2>
                <fdir1>0 0 1</fdir1>
                <slip1>0</slip1>
                <slip2>0</slip2>
              </ode>
            </friction>
            <contact>
              <ode>
                <min_depth>0.005</min_depth>
                <kp>1e+08</kp>
              </ode>
            </contact>
            <bounce/>
          </surface>
        </collision>
        <visual name='visual'>
          <pose>0 0 0 3.14159 -1.57079 3.14159</pose>
          <geometry>
            <mesh>
              <uri>model://polaris_ranger_xp900/meshes/polaris.dae</uri>
              <scale>1.0037 0.8862 0.8862</scale>
              <submesh>
                <name>Wheel_Front_Right</name>
                <center>1</center>
              </submesh>
            </mesh>
          </geometry>
          <material>
            <script>
              <uri>model://polaris_ranger_xp900/materials/scripts</uri>
              <uri>model://polaris_ranger_xp900/materials/textures</uri>
              <name>PolarisXP900/Diffuse</name>
            </script>
          </material>
        </visual>
        <velocity_decay>
          <linear>0</linear>
          <angular>0</angular>
        </velocity_decay>
        <self_collide>0</self_collide>
        <kinematic>0</kinematic>
        <gravity>1</gravity>
      </link>
      <link name='rear_left_wheel'>
        <pose>-0.99377 0.71562 0.34697 -1.52 0 0</pose>
        <inertial>
          <mass>12</mass>
          <inertia>
            <ixx>0.5</ixx>
            <ixy>0</ixy>
            <iyy>0.5</iyy>
            <ixz>0</ixz>
            <iyz>0</iyz>
            <izz>1</izz>
          </inertia>
        </inertial>
        <collision name='collision'>
          <geometry>
            <cylinder>
              <radius>0.3175</radius>
              <length>0.2794</length>
            </cylinder>
          </geometry>
          <max_contacts>1</max_contacts>
          <surface>
            <friction>
              <ode>
                <mu>1</mu>
                <mu2>1</mu2>
                <fdir1>0 0 1</fdir1>
                <slip1>0</slip1>
                <slip2>0</slip2>
              </ode>
            </friction>
            <contact>
              <ode>
                <min_depth>0.005</min_depth>
                <kp>1e+08</kp>
              </ode>
            </contact>
            <bounce/>
          </surface>
        </collision>
        <visual name='visual'>
          <pose>0 0 0 3.14159 -1.57079 3.14159</pose>
          <geometry>
            <mesh>
              <uri>model://polaris_ranger_xp900/meshes/polaris.dae</uri>
              <scale>1.0037 0.8862 0.8862</scale>
              <submesh>
                <name>Wheels_Rear_Left</name>
                <center>1</center>
              </submesh>
            </mesh>
          </geometry>
          <material>
            <script>
              <uri>model://polaris_ranger_xp900/materials/scripts</uri>
              <uri>model://polaris_ranger_xp900/materials/textures</uri>
              <name>PolarisXP900/Diffuse</name>
            </script>
          </material>
        </visual>
        <velocity_decay>
          <linear>0</linear>
          <angular>0</angular>
        </velocity_decay>
        <self_collide>0</self_collide>
        <kinematic>0</kinematic>
        <gravity>1</gravity>
      </link>
      <link name='rear_right_wheel'>
        <pose>-0.99377 -0.71562 0.34697 1.52 -0 0</pose>
        <inertial>
          <mass>12</mass>
          <inertia>
            <ixx>0.5</ixx>
            <ixy>0</ixy>
            <iyy>0.5</iyy>
            <ixz>0</ixz>
            <iyz>0</iyz>
            <izz>1</izz>
          </inertia>
        </inertial>
        <collision name='collision'>
          <geometry>
            <cylinder>
              <radius>0.3175</radius>
              <length>0.2794</length>
            </cylinder>
          </geometry>
          <max_contacts>1</max_contacts>
          <surface>
            <friction>
              <ode>
                <mu>1</mu>
                <mu2>1</mu2>
                <fdir1>0 0 1</fdir1>
                <slip1>0</slip1>
                <slip2>0</slip2>
              </ode>
            </friction>
            <contact>
              <ode>
                <min_depth>0.005</min_depth>
                <kp>1e+08</kp>
              </ode>
            </contact>
            <bounce/>
          </surface>
        </collision>
        <visual name='visual'>
          <pose>0 0 0 3.14159 -1.57079 3.14159</pose>
          <geometry>
            <mesh>
              <uri>model://polaris_ranger_xp900/meshes/polaris.dae</uri>
              <scale>1.0037 0.8862 0.8862</scale>
              <submesh>
                <name>Wheels_Rear_Right</name>
                <center>1</center>
              </submesh>
            </mesh>
          </geometry>
          <material>
            <script>
              <uri>model://polaris_ranger_xp900/materials/scripts</uri>
              <uri>model://polaris_ranger_xp900/materials/textures</uri>
              <name>PolarisXP900/Diffuse</name>
            </script>
          </material>
        </visual>
        <velocity_decay>
          <linear>0</linear>
          <angular>0</angular>
        </velocity_decay>
        <self_collide>0</self_collide>
        <kinematic>0</kinematic>
        <gravity>1</gravity>
      </link>
      <link name='gas_pedal'>
        <pose>0.63 0.1 0.58 0 -0 0</pose>
        <gravity>0</gravity>
        <inertial>
          <mass>0.1</mass>
          <pose>0 0 0 0 -0 0</pose>
          <inertia>
            <ixx>0.01</ixx>
            <ixy>0</ixy>
            <ixz>0</ixz>
            <iyy>0.01</iyy>
            <iyz>0</iyz>
            <izz>0.01</izz>
          </inertia>
        </inertial>
        <collision name='gas_pedal_collision'>
          <pose>-0.0385 0 -0.086 3.14159 1.12559 3.14159</pose>
          <geometry>
            <box>
              <size>0.1069 0.077 0.01</size>
            </box>
          </geometry>
          <max_contacts>10</max_contacts>
          <surface>
            <contact>
              <ode/>
            </contact>
            <bounce/>
            <friction>
              <ode/>
            </friction>
          </surface>
        </collision>
        <visual name='visual'>
          <pose>0 0 0 0 0 -1.5707</pose>
          <geometry>
            <mesh>
              <uri>model://polaris_ranger_xp900/meshes/polaris.dae</uri>
              <submesh>
                <name>Gas_Pedal</name>
                <center>1</center>
              </submesh>
            </mesh>
          </geometry>
          <material>
            <script>
              <uri>model://polaris_ranger_xp900/materials/scripts</uri>
              <uri>model://polaris_ranger_xp900/materials/textures</uri>
              <name>PolarisXP900/Diffuse</name>
            </script>
          </material>
        </visual>
        <velocity_decay>
          <linear>0</linear>
          <angular>0</angular>
        </velocity_decay>
        <self_collide>0</self_collide>
        <kinematic>0</kinematic>
      </link>
      <link name='brake_pedal'>
        <gravity>0</gravity>
        <pose>0.64 0.27 0.58 0 -0 0</pose>
        <inertial>
          <mass>0.1</mass>
          <pose>0 0 0 0 -0 0</pose>
          <inertia>
            <ixx>0.01</ixx>
            <ixy>0</ixy>
            <ixz>0</ixz>
            <iyy>0.01</iyy>
            <iyz>0</iyz>
            <izz>0.01</izz>
          </inertia>
        </inertial>
        <collision name='brake_pedal_collision'>
          <pose>-0.04 0 -0.086 3.14159 1.14259 3.14159</pose>
          <geometry>
            <box>
              <size>0.063 0.08 0.01</size>
            </box>
          </geometry>
          <max_contacts>10</max_contacts>
          <surface>
            <contact>
              <ode/>
            </contact>
            <bounce/>
            <friction>
              <ode/>
            </friction>
          </surface>
        </collision>
        <visual name='visual'>
          <pose>0 0 0 0 0 -1.5707</pose>
          <geometry>
            <mesh>
              <uri>model://polaris_ranger_xp900/meshes/polaris.dae</uri>
              <submesh>
                <name>Brake_Pedal</name>
                <center>1</center>
              </submesh>
            </mesh>
          </geometry>
          <material>
            <script>
              <uri>model://polaris_ranger_xp900/materials/scripts</uri>
              <uri>model://polaris_ranger_xp900/materials/textures</uri>
              <name>PolarisXP900/Diffuse</name>
            </script>
          </material>
        </visual>
        <velocity_decay>
          <linear>0</linear>
          <angular>0</angular>
        </velocity_decay>
        <self_collide>0</self_collide>
        <kinematic>0</kinematic>
      </link>
      <link name='front_right_wheel_steering_block'>
        <pose>1.20223 -0.5 0.35515 1.5708 -0 0</pose>
        <inertial>
          <mass>1</mass>
          <inertia>
            <ixx>1</ixx>
            <ixy>0</ixy>
            <iyy>1</iyy>
            <ixz>0</ixz>
            <iyz>0</iyz>
            <izz>1</izz>
          </inertia>
        </inertial>
        <collision name='collision'>
          <geometry>
            <cylinder>
              <radius>0.05</radius>
              <length>0.01</length>
            </cylinder>
          </geometry>
          <max_contacts>10</max_contacts>
          <surface>
            <contact>
              <ode/>
            </contact>
            <bounce/>
            <friction>
              <ode/>
            </friction>
          </surface>
        </collision>
        <velocity_decay>
          <linear>0</linear>
          <angular>0</angular>
        </velocity_decay>
        <self_collide>0</self_collide>
        <kinematic>0</kinematic>
        <gravity>1</gravity>
      </link>
      <link name='front_left_wheel_steering_block'>
        <pose>1.20223 0.5 0.35515 1.5708 -0 0</pose>
        <inertial>
          <mass>1</mass>
          <inertia>
            <ixx>1</ixx>
            <ixy>0</ixy>
            <iyy>1</iyy>
            <ixz>0</ixz>
            <iyz>0</iyz>
            <izz>1</izz>
          </inertia>
        </inertial>
        <collision name='collision'>
          <geometry>
            <cylinder>
              <radius>0.05</radius>
              <length>0.01</length>
            </cylinder>
          </geometry>
          <max_contacts>10</max_contacts>
          <surface>
            <contact>
              <ode/>
            </contact>
            <bounce/>
            <friction>
              <ode/>
            </friction>
          </surface>
        </collision>
        <velocity_decay>
          <linear>0</linear>
          <angular>0</angular>
        </velocity_decay>
        <self_collide>0</self_collide>
        <kinematic>0</kinematic>
        <gravity>1</gravity>
      </link>
      <link name='steering_wheel'>
        <pose>0.42 0.46 1.2 0 -0.87 0</pose>
        <inertial>
          <mass>1</mass>
          <pose>-0.002 0 0 0 -0 0</pose>
          <inertia>
            <ixx>0.012</ixx>
            <ixy>0</ixy>
            <ixz>0</ixz>
            <iyy>0.012</iyy>
            <iyz>0</iyz>
            <izz>0.024</izz>
          </inertia>
        </inertial>
        <collision name='collision'>
          <pose>-0.03 0 -0.120825 -0.6108 -5.55112e-17 -1.5708</pose>
          <geometry>
            <mesh>
              <uri>model://polaris_ranger_xp900/meshes/polaris.dae</uri>
              <submesh>
                <name>Steering_Wheel</name>
                <center>1</center>
              </submesh>
            </mesh>
          </geometry>
          <surface>
            <contact>
              <ode>
                <min_depth>0.003</min_depth>
              </ode>
            </contact>
            <bounce/>
            <friction>
              <ode/>
            </friction>
          </surface>
          <max_contacts>10</max_contacts>
        </collision>
        <visual name='visual'>
          <pose>-0.03 0 -0.120825 -0.6108 -5.55112e-17 -1.5708</pose>
          <geometry>
            <mesh>
              <uri>model://polaris_ranger_xp900/meshes/polaris.dae</uri>
              <submesh>
                <name>Steering_Wheel</name>
                <center>1</center>
              </submesh>
            </mesh>
          </geometry>
          <material>
            <script>
              <uri>model://polaris_ranger_xp900/materials/scripts</uri>
              <uri>model://polaris_ranger_xp900/materials/textures</uri>
              <name>PolarisXP900/Diffuse</name>
            </script>
          </material>
        </visual>
        <velocity_decay>
          <linear>0</linear>
          <angular>0</angular>
        </velocity_decay>
        <self_collide>0</self_collide>
        <kinematic>0</kinematic>
        <gravity>1</gravity>
      </link>
      <link name='hand_brake'>
        <pose>0.53 0.205 1.05 0 -0 0</pose>
        <inertial>
          <mass>0.5</mass>
          <inertia>
            <ixx>0.1</ixx>
            <ixy>0</ixy>
            <ixz>0</ixz>
            <iyy>0.1</iyy>
            <iyz>0</iyz>
            <izz>0.05</izz>
          </inertia>
        </inertial>
        <collision name='hand_brake_collision'>
          <pose>0 0 0.05 -0.2 -1.38778e-17 -1.5708</pose>
          <geometry>
            <mesh>
              <uri>model://polaris_ranger_xp900/meshes/polaris.dae</uri>
              <submesh>
                <name>Shifter</name>
                <center>1</center>
              </submesh>
            </mesh>
          </geometry>
          <max_contacts>10</max_contacts>
          <surface>
            <contact>
              <ode/>
            </contact>
            <bounce/>
            <friction>
              <ode/>
            </friction>
          </surface>
        </collision>
        <visual name='hand_brake_visual'>
          <pose>0 0 0.05 -0.2 -1.38778e-17 -1.5708</pose>
          <geometry>
            <mesh>
              <uri>model://polaris_ranger_xp900/meshes/polaris.dae</uri>
              <submesh>
                <name>Shifter</name>
                <center>1</center>
              </submesh>
            </mesh>
          </geometry>
          <material>
            <script>
              <uri>model://polaris_ranger_xp900/materials/scripts</uri>
              <uri>model://polaris_ranger_xp900/materials/textures</uri>
              <name>PolarisXP900/Diffuse</name>
            </script>
          </material>
        </visual>
        <velocity_decay>
          <linear>0</linear>
          <angular>0</angular>
        </velocity_decay>
        <self_collide>0</self_collide>
        <kinematic>0</kinematic>
        <gravity>1</gravity>
      </link>
      <link name='FNR_switch'>
        <pose>0.54 0.1 1.15 0 0.25 0</pose>
        <inertial>
          <mass>0.1</mass>
          <inertia>
            <ixx>0.1</ixx>
            <ixy>0</ixy>
            <ixz>0</ixz>
            <iyy>6e-05</iyy>
            <iyz>0</iyz>
            <izz>0.1</izz>
          </inertia>
        </inertial>
        <collision name='FNR_switch'>
          <geometry>
            <box>
              <size>0.02 0.04 0.08</size>
            </box>
          </geometry>
          <max_contacts>10</max_contacts>
          <surface>
            <contact>
              <ode/>
            </contact>
            <bounce/>
            <friction>
              <ode/>
            </friction>
          </surface>
        </collision>
        <visual name='FNR_switch_F'>
          <transparency>0</transparency>
          <geometry>
            <box>
              <size>0.02 0.04 0.08</size>
            </box>
          </geometry>
          <material>
            <script>
              <uri>model://polaris_ranger_ev/materials/scripts</uri>
              <uri>model://polaris_ranger_ev/materials/textures</uri>
              <name>FNR_switch_F</name>
            </script>
          </material>
        </visual>
        <visual name='FNR_switch_R'>
          <transparency>1</transparency>
          <geometry>
            <box>
              <size>0.0199 0.0399 0.0799</size>
            </box>
          </geometry>
          <material>
            <script>
              <uri>model://polaris_ranger_ev/materials/scripts</uri>
              <uri>model://polaris_ranger_ev/materials/textures</uri>
              <name>FNR_switch_R</name>
            </script>
          </material>
        </visual>
        <velocity_decay>
          <linear>0</linear>
          <angular>0</angular>
        </velocity_decay>
        <self_collide>0</self_collide>
        <kinematic>0</kinematic>
        <gravity>1</gravity>
      </link>
      <joint name='front_left_steering_joint' type='revolute'>
        <child>front_left_wheel_steering_block</child>
        <parent>chassis</parent>
        <axis>
          <xyz>0 0 1</xyz>
          <limit>
            <lower>-0.7727</lower>
            <upper>0.7727</upper>
          </limit>
          <dynamics>
            <damping>50</damping>
            <spring_reference>0</spring_reference>
            <spring_stiffness>0</spring_stiffness>
          </dynamics>
          <use_parent_model_frame>1</use_parent_model_frame>
        </axis>
        <physics>
          <ode>
            <cfm_damping>1</cfm_damping>
            <limit>
              <cfm>0</cfm>
              <erp>0.9</erp>
            </limit>
          </ode>
        </physics>
      </joint>
      <joint name='front_left_wheel_joint' type='revolute'>
        <child>front_left_wheel</child>
        <parent>front_left_wheel_steering_block</parent>
        <axis>
          <xyz>0 1 0.05</xyz>
          <use_parent_model_frame>1</use_parent_model_frame>
          <limit>
            <lower>-1e+16</lower>
            <upper>1e+16</upper>
          </limit>
          <dynamics>
            <spring_reference>0</spring_reference>
            <spring_stiffness>0</spring_stiffness>
          </dynamics>
        </axis>
      </joint>
      <joint name='front_right_steering_joint' type='revolute'>
        <child>front_right_wheel_steering_block</child>
        <parent>chassis</parent>
        <axis>
          <xyz>0 0 1</xyz>
          <limit>
            <lower>-0.7727</lower>
            <upper>0.7727</upper>
          </limit>
          <dynamics>
            <damping>50</damping>
            <spring_reference>0</spring_reference>
            <spring_stiffness>0</spring_stiffness>
          </dynamics>
          <use_parent_model_frame>1</use_parent_model_frame>
        </axis>
        <physics>
          <ode>
            <cfm_damping>1</cfm_damping>
            <limit>
              <cfm>0</cfm>
              <erp>0.9</erp>
            </limit>
          </ode>
        </physics>
      </joint>
      <joint name='front_right_wheel_joint' type='revolute'>
        <child>front_right_wheel</child>
        <parent>front_right_wheel_steering_block</parent>
        <axis>
          <xyz>0 1 -0.05</xyz>
          <use_parent_model_frame>1</use_parent_model_frame>
          <limit>
            <lower>-1e+16</lower>
            <upper>1e+16</upper>
          </limit>
          <dynamics>
            <spring_reference>0</spring_reference>
            <spring_stiffness>0</spring_stiffness>
          </dynamics>
        </axis>
      </joint>
      <joint name='rear_left_wheel_joint' type='revolute'>
        <child>rear_left_wheel</child>
        <parent>chassis</parent>
        <axis>
          <xyz>0 1 0.05</xyz>
          <use_parent_model_frame>1</use_parent_model_frame>
          <limit>
            <lower>-1e+16</lower>
            <upper>1e+16</upper>
          </limit>
          <dynamics>
            <spring_reference>0</spring_reference>
            <spring_stiffness>0</spring_stiffness>
          </dynamics>
        </axis>
      </joint>
      <joint name='rear_right_wheel_joint' type='revolute'>
        <pose>0 0 -0.1 0 -0 0</pose>
        <child>rear_right_wheel</child>
        <parent>chassis</parent>
        <axis>
          <xyz>0 1 -0.05</xyz>
          <use_parent_model_frame>1</use_parent_model_frame>
          <limit>
            <lower>-1e+16</lower>
            <upper>1e+16</upper>
          </limit>
          <dynamics>
            <spring_reference>0</spring_reference>
            <spring_stiffness>0</spring_stiffness>
          </dynamics>
        </axis>
      </joint>
      <joint name='rear_differential_joint' type='revolute'>
        <child>rear_right_wheel</child>
        <parent>rear_left_wheel</parent>
        <axis>
          <xyz>0 1 0</xyz>
          <dynamics>
            <damping>70</damping>
            <spring_reference>0</spring_reference>
            <spring_stiffness>0</spring_stiffness>
          </dynamics>
          <use_parent_model_frame>1</use_parent_model_frame>
          <limit>
            <lower>-1e+16</lower>
            <upper>1e+16</upper>
          </limit>
        </axis>
        <physics>
          <ode>
            <erp>0</erp>
            <cfm>1000</cfm>
            <cfm_damping>1</cfm_damping>
            <limit>
              <cfm>0</cfm>
              <erp>0.2</erp>
            </limit>
          </ode>
        </physics>
      </joint>
      <joint name='gas_joint' type='prismatic'>
        <parent>chassis</parent>
        <child>gas_pedal</child>
        <axis>
          <xyz>1 0 -1</xyz>
          <limit>
            <lower>0</lower>
            <upper>0.08</upper>
          </limit>
          <dynamics>
            <damping>3</damping>
            <spring_reference>0</spring_reference>
            <spring_stiffness>0</spring_stiffness>
          </dynamics>
          <use_parent_model_frame>1</use_parent_model_frame>
        </axis>
        <physics>
          <ode>
            <cfm_damping>1</cfm_damping>
            <limit>
              <cfm>0</cfm>
              <erp>0.2</erp>
            </limit>
          </ode>
        </physics>
      </joint>
      <joint name='brake_joint' type='prismatic'>
        <parent>chassis</parent>
        <child>brake_pedal</child>
        <axis>
          <xyz>1 0 -0.6</xyz>
          <limit>
            <lower>0</lower>
            <upper>0.08</upper>
          </limit>
          <dynamics>
            <damping>3</damping>
            <spring_reference>0</spring_reference>
            <spring_stiffness>0</spring_stiffness>
          </dynamics>
          <use_parent_model_frame>1</use_parent_model_frame>
        </axis>
        <physics>
          <ode>
            <cfm_damping>1</cfm_damping>
            <limit>
              <cfm>0</cfm>
              <erp>0.2</erp>
            </limit>
          </ode>
        </physics>
      </joint>
      <joint name='steering_joint' type='revolute'>
        <pose>0 0 0 0 -0 0</pose>
        <parent>chassis</parent>
        <child>steering_wheel</child>
        <axis>
          <xyz>-1 0 0.84365</xyz>
          <limit>
            <lower>-3.14</lower>
            <upper>3.14</upper>
          </limit>
          <dynamics>
            <damping>1</damping>
            <spring_reference>0</spring_reference>
            <spring_stiffness>0</spring_stiffness>
          </dynamics>
          <use_parent_model_frame>1</use_parent_model_frame>
        </axis>
        <physics>
          <ode>
            <cfm_damping>1</cfm_damping>
            <limit>
              <cfm>0</cfm>
              <erp>0.2</erp>
            </limit>
          </ode>
        </physics>
      </joint>
      <joint name='hand_brake_joint' type='revolute'>
        <parent>chassis</parent>
        <child>hand_brake</child>
        <axis>
          <xyz>0 -1 0</xyz>
          <limit>
            <lower>0</lower>
            <upper>0.6</upper>
          </limit>
          <dynamics>
            <damping>1</damping>
            <spring_reference>0</spring_reference>
            <spring_stiffness>0</spring_stiffness>
          </dynamics>
          <use_parent_model_frame>1</use_parent_model_frame>
        </axis>
        <physics>
          <ode>
            <cfm_damping>1</cfm_damping>
            <limit>
              <cfm>0</cfm>
              <erp>0.2</erp>
            </limit>
          </ode>
        </physics>
      </joint>
      <joint name='FNR_switch_joint' type='revolute'>
        <parent>chassis</parent>
        <child>FNR_switch</child>
        <axis>
          <xyz>0 -1 0</xyz>
          <limit>
            <lower>-0.3</lower>
            <upper>0.3</upper>
          </limit>
          <dynamics>
            <damping>0.01</damping>
            <spring_reference>0</spring_reference>
            <spring_stiffness>0</spring_stiffness>
          </dynamics>
          <use_parent_model_frame>1</use_parent_model_frame>
        </axis>
        <physics>
          <ode>
            <cfm_damping>1</cfm_damping>
            <limit>
              <cfm>0</cfm>
              <erp>0.2</erp>
            </limit>
          </ode>
        </physics>
      </joint>
      <pose>39 -46 0 0 -0 0</pose>
      <plugin name="model_plugin" filename="libmodel_plugin.so"/>
    </model>
  </world>
</sdf>
